Workbook

Sheet Start Here
A1: Tiny Sparks — 800-video content calendar
A2: One video a day for 800 days (~2.2 years). Edit only the YELLOW cells and the blue columns; black cells are calculated.
A4: Setting | B4: Value | C4: What it does
A5: Launch date (Day 1, a Monday) | B5: 46314 | C5: Every date in the Calendar = launch date + (Day # − 1). Keep it a Monday so the theme days stay on their weekdays.
A6: Hours from ET to YOUR time | B6: 5 | C6: Times are planned in US Eastern (ET), the biggest English kids audience. Morocco/Western Europe ≈ +5 to +6 (US clocks change 1 Nov and in March).
A8: Post time by weekday (ET)
A9: Weekday | B9: Time (ET) | C9: Why
A10: Monday | B10: 0.66666667 | C10: after school / after nap — kids + parent co-viewing
A11: Tuesday | B11: 0.66666667
A12: Wednesday | B12: 0.66666667
A13: Thursday | B13: 0.66666667
A14: Friday | B14: 0.66666667 | C14: start of the weekend binge
A15: Saturday | B15: 0.375 | C15: weekend morning: the biggest kids-viewing window
A16: Sunday | B16: 0.375 | C16: weekend morning (songs)
A18: Weekly rotation
A19: Monday | B19: Story Monday: 🧠 Educational Story (odd weeks) / 📚 Moral Story (even weeks)
A20: Tuesday | B20: Math Tuesday: 🔢 Numbers & Math
A21: Wednesday | B21: Word Wednesday: 🔤 English/French
A22: Thursday | B22: Animal Thursday: 🦁 Animal Story
A23: Friday | B23: Science Friday: 🚀 Science
A24: Saturday | B24: Puzzle Saturday: 🧩 Puzzle
A25: Sunday | B25: Song Sunday: 🎵 Song
A26: After week 100 | B26: Story Season (days 701–800): the remaining 50 educational + 50 moral stories, alternating daily
A28: Status
A29: Idea | B29: not started
A30: Scripted | B30: script.md + beats.json done
A31: Rendered | B31: final MP4 exported
A32: Scheduled | B32: uploaded + scheduled in YouTube Studio
A33: Published | B33: live: paste the link, add views after 48 h and 7 days
A35: Columns in the Calendar
A36: YouTube title | B36: the idea adapted to the locked cast (Tommy/Max/Alex → Leo, Mia/Emma/Lily/Sara → Mila, Benny → Bobo) + niche tag + channel
A37: Age | B37: 3–5 / 6–8 / 9–12, estimated from the topic; adjust freely
A38: Format / Length | B38: Short 9:16 vs long 16:9 (+ a Short cut), from the niche skill rules
A39: Rig ready? | B39: "Yes" = every animal in it already exists in the Critter rig; otherwise the species to add to critter.tsx first
A40: Priority | B40: P1 = first 13 weeks, P2 = rest of year 1, P3 = later. A "Build first" in the first 13 weeks is the to-do list for the art kit.

Sheet Calendar
A1: Day # | B1: Week | C1: Date | D1: Day | E1: Theme day | F1: Niche | G1: Niche # | H1: Idea (original) | I1: YouTube title | J1: Age | K1: Format | L1: Length | M1: Characters | N1: Learning objective | O1: Rig ready? | P1: Priority | Q1: Status | R1: Post time (ET) | S1: Your time | T1: YouTube link | U1: Views 48h | V1: Views 7 days | W1: Subs gained | X1: Avg % viewed | Y1: Notes
A2: 1 | B2: =INT((A2-1)/7)+1 | C2: ='Start Here'!$B$5+A2-1 | D2: =TEXT(C2,"ddd") | E2: Story Monday | F2: 🧠 Educational Stories | G2: 1 | H2: Tommy Learns Why We Should Share | I2: Leo Learns Why We Should Share 🧠 | Kids Stories | Tiny Sparks | J2: 3–5 | K2: Long 16:9 + Short teaser | L2: 3–5 min (Short: 50 s) | M2: Leo (lead) · Mila, Leo, Bobo + narrator | N2: Life skill: We Should Share | O2: Yes | P2: P1 | Q2: Rendered | R2: =INDEX('Start Here'!$B$10:$B$16,WEEKDAY(C2,2)) | S2: =MOD(R2+'Start Here'!$B$6/24,1) | Y2: made 2026-10-07 → kids-shorts/tiny-sparks/stories/day-001-leo-learns-why-we-should-share/output/day-001-sfx-music.mp4
A3: 2 | B3: =INT((A3-1)/7)+1 | C3: ='Start Here'!$B$5+A3-1 | D3: =TEXT(C3,"ddd") | E3: Math Tuesday | F3: 🔢 Numbers & Math | G3: 1 | H3: Learn Numbers 1–10 with Animals | I3: Learn Numbers 1–10 with Animals 🔢 | Learn Math for Kids | Tiny Sparks | J3: 3–5 | K3: Short 9:16 | L3: 45–60 s | M3: Bobo + Mila (counting fingers) | N3: Math: Learn Numbers 1–10 with Animals | O3: Yes | P3: P1 | Q3: Rendered | R3: =INDEX('Start Here'!$B$10:$B$16,WEEKDAY(C3,2)) | S3: =MOD(R3+'Start Here'!$B$6/24,1) | Y3: made 2026-10-07 → kids-shorts/tiny-sparks/numbers/day-002-learn-numbers-1-10-with-animals/output/day-002-sfx-music.mp4
A4: 3 | B4: =INT((A4-1)/7)+1 | C4: ='Start Here'!$B$5+A4-1 | D4: =TEXT(C4,"ddd") | E4: Word Wednesday | F4: 🔤 English/French Words | G4: 1 | H4: 20 Animals in English and French | I4: 20 Animals in English and French 🔤 | Kids Vocabulary | Tiny Sparks | J4: 3–5 | K4: Long 16:9 | L4: 4–8 min | M4: Mila + French narrator | N4: Vocabulary EN→FR: 20 Animals | O4: Yes | P4: P1 | Q4: Rendered | R4: =INDEX('Start Here'!$B$10:$B$16,WEEKDAY(C4,2)) | S4: =MOD(R4+'Start Here'!$B$6/24,1) | Y4: made 2026-10-08 → kids-shorts/tiny-sparks/words/day-003-20-animals-in-english-and-french/output/day-003-sfx-music.mp4
A5: 4 | B5: =INT((A5-1)/7)+1 | C5: ='Start Here'!$B$5+A5-1 | D5: =TEXT(C5,"ddd") | E5: Animal Thursday | F5: 🦁 Animal Stories | G5: 1 | H5: Leo the Lion Who Was Afraid of the Dark | I5: Rory the Lion Who Was Afraid of the Dark 🦁 | Animal Stories for Kids | Tiny Sparks | J5: 3–5 | K5: Long 16:9 + Short teaser | L5: 3–5 min (Short: 50 s) | M5: guest animal(s) + Bobo | N5: Story + 3 true animal facts; value: courage | O5: Yes | P5: P1 | Q5: Rendered | R5: =INDEX('Start Here'!$B$10:$B$16,WEEKDAY(C5,2)) | S5: =MOD(R5+'Start Here'!$B$6/24,1) | Y5: made 2026-10-08 → kids-shorts/tiny-sparks/animals/day-004-rory-the-lion-who-was-afraid-of-the-dark/output/day-004-final.mp4
A6: 5 | B6: =INT((A6-1)/7)+1 | C6: ='Start Here'!$B$5+A6-1 | D6: =TEXT(C6,"ddd") | E6: Science Friday | F6: 🚀 Science for Kids | G6: 1 | H6: Why Is the Sky Blue? | I6: Why Is the Sky Blue? 🚀 | Science for Kids | Tiny Sparks | J6: 3–5 | K6: Short 9:16 | L6: 45–60 s | M6: Prof. Hoot + Leo (wrong guess) + Mila | N6: Answer simply: Why Is the Sky Blue? | O6: Yes | P6: P1 | Q6: Rendered | R6: =INDEX('Start Here'!$B$10:$B$16,WEEKDAY(C6,2)) | S6: =MOD(R6+'Start Here'!$B$6/24,1) | Y6: made 2026-10-09 → kids-shorts/tiny-sparks/science/day-005-why-is-the-sky-blue/output/day-005-final.mp4
A7: 6 | B7: =INT((A7-1)/7)+1 | C7: ='Start Here'!$B$5+A7-1 | D7: =TEXT(C7,"ddd") | E7: Puzzle Saturday | F7: 🧩 Puzzles & Problem-Solving | G7: 1 | H7: Find the Missing Number | I7: Find the Missing Number 🧩 | Brain Games for Kids | Tiny Sparks | J7: 3–5 | K7: Short 9:16 | L7: 45–60 s | M7: Prof. Hoot + Leo + score strip | N7: Thinking skill: observation | O7: Yes | P7: P1 | Q7: Rendered | R7: =INDEX('Start Here'!$B$10:$B$16,WEEKDAY(C7,2)) | S7: =MOD(R7+'Start Here'!$B$6/24,1) | Y7: made 2026-10-09 → kids-shorts/tiny-sparks/puzzles/day-006-find-the-missing-number/output/day-006-final.mp4
A8: 7 | B8: =INT((A8-1)/7)+1 | C8: ='Start Here'!$B$5+A8-1 | D8: =TEXT(C8,"ddd") | E8: Song Sunday | F8: 🎵 Educational Songs | G8: 1 | H8: Count from 1 to 10 Song | I8: Count from 1 to 10 Song 🎵 | Kids Songs | Tiny Sparks | J8: 3–5 | K8: Long 16:9 + Short cut | L8: 2–3 min (Short: 45 s chorus) | M8: Mila sings, all dance | N8: Sing & learn: Count from 1 to 10 | O8: Yes | P8: P1 | Q8: Rendered | R8: =INDEX('Start Here'!$B$10:$B$16,WEEKDAY(C8,2)) | S8: =MOD(R8+'Start Here'!$B$6/24,1) | Y8: made 2026-10-09 → kids-shorts/tiny-sparks/songs/day-007-count-from-1-to-10-song/output/day-007-final.mp4
A9: 8 | B9: =INT((A9-1)/7)+1 | C9: ='Start Here'!$B$5+A9-1 | D9: =TEXT(C9,"ddd") | E9: Story Monday | F9: 📚 Moral Stories | G9: 1 | H9: The Boy Who Always Told the Truth | I9: The Boy Who Always Told the Truth 📚 | Moral Stories for Kids | Tiny Sparks | J9: 3–5 | K9: Long 16:9 + Short teaser | L9: 3–5 min (Short: 50 s) | M9: narrator + guest animals / Mila & Leo | N9: Value: honesty | O9: Yes | P9: P1 | Q9: Rendered | R9: =INDEX('Start Here'!$B$10:$B$16,WEEKDAY(C9,2)) | S9: =MOD(R9+'Start Here'!$B$6/24,1) | Y9: made 2026-10-09 → kids-shorts/tiny-sparks/morals/day-008-the-boy-who-always-told-the-truth/output/day-008-final.mp4
A10: 9 | B10: =INT((A10-1)/7)+1 | C10: ='Start Here'!$B$5+A10-1 | D10: =TEXT(C10,"ddd") | E10: Math Tuesday | F10: 🔢 Numbers & Math | G10: 2 | H10: Counting 1–20 with Balloons | I10: Counting 1–20 with Balloons 🔢 | Learn Math for Kids | Tiny Sparks | J10: 3–5 | K10: Short 9:16 | L10: 45–60 s | M10: Bobo + Mila (counting fingers) | N10: Math: Counting 1–20 with Balloons | O10: Yes | P10: P1 | Q10: Rendered | R10: =INDEX('Start Here'!$B$10:$B$16,WEEKDAY(C10,2)) | S10: =MOD(R10+'Start Here'!$B$6/24,1) | Y10: made 2026-10-09 → kids-shorts/tiny-sparks/numbers/day-009-counting-1-20-with-balloons/output/day-009-final.mp4
A11: 10 | B11: =INT((A11-1)/7)+1 | C11: ='Start Here'!$B$5+A11-1 | D11: =TEXT(C11,"ddd") | E11: Word Wednesday | F11: 🔤 English/French Words | G11: 2 | H11: 20 Colors in English and French | I11: 20 Colors in English and French 🔤 | Kids Vocabulary | Tiny Sparks | J11: 3–5 | K11: Long 16:9 | L11: 4–8 min | M11: Mila + French narrator | N11: Vocabulary EN→FR: 20 Colors | O11: Yes | P11: P1 | Q11: Rendered | R11: =INDEX('Start Here'!$B$10:$B$16,WEEKDAY(C11,2)) | S11: =MOD(R11+'Start Here'!$B$6/24,1) | Y11: made 2026-10-09 → kids-shorts/tiny-sparks/words/day-010-20-colors-in-english-and-french/output/day-010-final.mp4
A12: 11 | B12: =INT((A12-1)/7)+1 | C12: ='Start Here'!$B$5+A12-1 | D12: =TEXT(C12,"ddd") | E12: Animal Thursday | F12: 🦁 Animal Stories | G12: 2 | H12: Benny the Rabbit and the Lost Carrot | I12: Benny the Rabbit and the Lost Carrot 🦁 | Animal Stories for Kids | Tiny Sparks | J12: 3–5 | K12: Long 16:9 + Short teaser | L12: 3–5 min (Short: 50 s) | M12: guest animal(s) + Bobo | N12: Story + 3 true animal facts; value: friendship | O12: Yes | P12: P1 | Q12: Rendered | R12: =INDEX('Start Here'!$B$10:$B$16,WEEKDAY(C12,2)) | S12: =MOD(R12+'Start Here'!$B$6/24,1) | Y12: made 2026-10-09 → kids-shorts/tiny-sparks/animals/day-011-benny-the-rabbit-and-the-lost-carrot/output/day-011-final.mp4
A13: 12 | B13: =INT((A13-1)/7)+1 | C13: ='Start Here'!$B$5+A13-1 | D13: =TEXT(C13,"ddd") | E13: Science Friday | F13: 🚀 Science for Kids | G13: 2 | H13: Why Does the Sun Shine? | I13: Why Does the Sun Shine? 🚀 | Science for Kids | Tiny Sparks | J13: 3–5 | K13: Short 9:16 | L13: 45–60 s | M13: Prof. Hoot + Leo (wrong guess) + Mila | N13: Answer simply: Why Does the Sun Shine? | O13: Yes | P13: P1 | Q13: Rendered | R13: =INDEX('Start Here'!$B$10:$B$16,WEEKDAY(C13,2)) | S13: =MOD(R13+'Start Here'!$B$6/24,1) | Y13: made 2026-10-09 → kids-shorts/tiny-sparks/science/day-012-why-does-the-sun-shine/output/day-012-final.mp4
... A36: 35 | B36: =INT((A36-1)/7)+1 | C36: ='Start Here'!$B$5+A36-1 | D36: =TEXT(C36,"ddd") | E36: Song Sunday | F36: 🎵 Educational Songs | G36: 5 | H36: Shapes Song | I36: Shapes Song 🎵 | Kids Songs | Tiny Sparks | J36: 3–5 | K36: Long 16:9 + Short cut | L36: 2–3 min (Short: 45 s chorus) | M36: Mila sings, all dance | N36: Sing & learn: Shapes | O36: Yes | P36: P1 | Q36: Rendered | R36: =INDEX('Start Here'!$B$10:$B$16,WEEKDAY(C36,2)) | S36: =MOD(R36+'Start Here'!$B$6/24,1) | Y36: made 2026-10-21 → kids-shorts/tiny-sparks/songs/day-035-shapes-song/output/day-035-final.mp4
A37: 36 | B37: =INT((A37-1)/7)+1 | C37: ='Start Here'!$B$5+A37-1 | D37: =TEXT(C37,"ddd") | E37: Story Monday | F37: 📚 Moral Stories | G37: 3 | H37: The Greedy Little Monkey | I37: The Greedy Little Monkey 📚 | Moral Stories for Kids | Tiny Sparks | J37: 3–5 | K37: Long 16:9 + Short teaser | L37: 3–5 min (Short: 50 s) | M37: narrator + guest animals / Mila & Leo | N37: Value: sharing | O37: Build first: monkey | P37: P1 | Q37: Idea | R37: =INDEX('Start Here'!$B$10:$B$16,WEEKDAY(C37,2)) | S37: =MOD(R37+'Start Here'!$B$6/24,1)
A38: 37 | B38: =INT((A38-1)/7)+1 | C38: ='Start Here'!$B$5+A38-1 | D38: =TEXT(C38,"ddd") | E38: Math Tuesday | F38: 🔢 Numbers & Math | G38: 6 | H38: Numbers 1–20 with Dinosaurs | I38: Numbers 1–20 with Dinosaurs 🔢 | Learn Math for Kids | Tiny Sparks | J38: 6–8 | K38: Long 16:9 | L38: 4–8 min | M38: Bobo + Mila (counting fingers) | N38: Math: Numbers 1–20 with Dinosaurs | O38: Build first: dinosaurs | P38: P1 | Q38: Idea | R38: =INDEX('Start Here'!$B$10:$B$16,WEEKDAY(C38,2)) | S38: =MOD(R38+'Start Here'!$B$6/24,1)
A39: 38 | B39: =INT((A39-1)/7)+1 | C39: ='Start Here'!$B$5+A39-1 | D39: =TEXT(C39,"ddd") | E39: Word Wednesday | F39: 🔤 English/French Words | G39: 6 | H39: Vegetables English/French | I39: Vegetables English/French 🔤 | Kids Vocabulary | Tiny Sparks | J39: 3–5 | K39: Short 9:16 | L39: 45–60 s | M39: Mila + French narrator | N39: Vocabulary EN→FR: Vegetables | O39: Yes | P39: P1 | Q39: Idea | R39: =INDEX('Start Here'!$B$10:$B$16,WEEKDAY(C39,2)) | S39: =MOD(R39+'Start Here'!$B$6/24,1)
A40: 39 | B40: =INT((A40-1)/7)+1 | C40: ='Start Here'!$B$5+A40-1 | D40: =TEXT(C40,"ddd") | E40: Animal Thursday | F40: 🦁 Animal Stories | G40: 6 | H40: Oliver the Owl's First Flight | I40: Oliver the Owl's First Flight 🦁 | Animal Stories for Kids | Tiny Sparks | J40: 3–5 | K40: Long 16:9 + Short teaser | L40: 3–5 min (Short: 50 s) | M40: guest animal(s) + Bobo | N40: Story + 3 true animal facts; value: friendship | O40: Yes | P40: P1 | Q40: Idea | R40: =INDEX('Start Here'!$B$10:$B$16,WEEKDAY(C40,2)) | S40: =MOD(R40+'Start Here'!$B$6/24,1)
A41: 40 | B41: =INT((A41-1)/7)+1 | C41: ='Start Here'!$B$5+A41-1 | D41: =TEXT(C41,"ddd") | E41: Science Friday | F41: 🚀 Science for Kids | G41: 6 | H41: What Are Clouds? | I41: What Are Clouds? 🚀 | Science for Kids | Tiny Sparks | J41: 3–5 | K41: Short 9:16 | L41: 45–60 s | M41: Prof. Hoot + Leo (wrong guess) + Mila | N41: Answer simply: What Are Clouds? | O41: Yes | P41: P1 | Q41: Idea | R41: =INDEX('Start Here'!$B$10:$B$16,WEEKDAY(C41,2)) | S41: =MOD(R41+'Start Here'!$B$6/24,1)
A42: 41 | B42: =INT((A42-1)/7)+1 | C42: ='Start Here'!$B$5+A42-1 | D42: =TEXT(C42,"ddd") | E42: Puzzle Saturday | F42: 🧩 Puzzles & Problem-Solving | G42: 6 | H42: Find the Different Animal | I42: Find the Different Animal 🧩 | Brain Games for Kids | Tiny Sparks | J42: 3–5 | K42: Short 9:16 | L42: 45–60 s | M42: Prof. Hoot + Leo + score strip | N42: Thinking skill: observation | O42: Yes | P42: P1 | Q42: Idea | R42: =INDEX('Start Here'!$B$10:$B$16,WEEKDAY(C42,2)) | S42: =MOD(R42+'Start Here'!$B$6/24,1)
A43: 42 | B43: =INT((A43-1)/7)+1 | C43: ='Start Here'!$B$5+A43-1 | D43: =TEXT(C43,"ddd") | E43: Song Sunday | F43: 🎵 Educational Songs | G43: 6 | H43: Days of the Week Song | I43: Days of the Week Song 🎵 | Kids Songs | Tiny Sparks | J43: 3–5 | K43: Long 16:9 + Short cut | L43: 2–3 min (Short: 45 s chorus) | M43: Mila sings, all dance | N43: Sing & learn: Days of the Week | O43: Yes | P43: P1 | Q43: Idea | R43: =INDEX('Start Here'!$B$10:$B$16,WEEKDAY(C43,2)) | S43: =MOD(R43+'Start Here'!$B$6/24,1)
A44: 43 | B44: =INT((A44-1)/7)+1 | C44: ='Start Here'!$B$5+A44-1 | D44: =TEXT(C44,"ddd") | E44: Story Monday | F44: 🧠 Educational Stories | G44: 4 | H44: The Day Emma Learned Patience | I44: The Day Mila Learned Patience 🧠 | Kids Stories | Tiny Sparks | J44: 3–5 | K44: Long 16:9 + Short teaser | L44: 3–5 min (Short: 50 s) | M44: Mila (lead) · Mila, Leo, Bobo + narrator | N44: Life skill: Patience | O44: Yes | P44: P1 | Q44: Idea | R44: =INDEX('Start Here'!$B$10:$B$16,WEEKDAY(C44,2)) | S44: =MOD(R44+'Start Here'!$B$6/24,1)
A45: 44 | B45: =INT((A45-1)/7)+1 | C45: ='Start Here'!$B$5+A45-1 | D45: =TEXT(C45,"ddd") | E45: Math Tuesday | F45: 🔢 Numbers & Math | G45: 7 | H45: Count the Farm Animals | I45: Count the Farm Animals 🔢 | Learn Math for Kids | Tiny Sparks | J45: 3–5 | K45: Short 9:16 | L45: 45–60 s | M45: Bobo + Mila (counting fingers) | N45: Math: Count the Farm Animals | O45: Build first: farm animals | P45: P1 | Q45: Idea | R45: =INDEX('Start Here'!$B$10:$B$16,WEEKDAY(C45,2)) | S45: =MOD(R45+'Start Here'!$B$6/24,1)
A46: 45 | B46: =INT((A46-1)/7)+1 | C46: ='Start Here'!$B$5+A46-1 | D46: =TEXT(C46,"ddd") | E46: Word Wednesday | F46: 🔤 English/French Words | G46: 7 | H46: School Objects English/French | I46: School Objects English/French 🔤 | Kids Vocabulary | Tiny Sparks | J46: 3–5 | K46: Short 9:16 | L46: 45–60 s | M46: Mila + French narrator | N46: Vocabulary EN→FR: School Objects | O46: Yes | P46: P1 | Q46: Idea | R46: =INDEX('Start Here'!$B$10:$B$16,WEEKDAY(C46,2)) | S46: =MOD(R46+'Start Here'!$B$6/24,1)
A47: 46 | B47: =INT((A47-1)/7)+1 | C47: ='Start Here'!$B$5+A47-1 | D47: =TEXT(C47,"ddd") | E47: Animal Thursday | F47: 🦁 Animal Stories | G47: 7 | H47: Coco the Penguin Finds a Friend | I47: Coco the Penguin Finds a Friend 🦁 | Animal Stories for Kids | Tiny Sparks | J47: 3–5 | K47: Long 16:9 + Short teaser | L47: 3–5 min (Short: 50 s) | M47: guest animal(s) + Bobo | N47: Story + 3 true animal facts; value: friendship | O47: Build first: penguin | P47: P1 | Q47: Idea | R47: =INDEX('Start Here'!$B$10:$B$16,WEEKDAY(C47,2)) | S47: =MOD(R47+'Start Here'!$B$6/24,1)
A48: 47 | B48: =INT((A48-1)/7)+1 | C48: ='Start Here'!$B$5+A48-1 | D48: =TEXT(C48,"ddd") | E48: Science Friday | F48: 🚀 Science for Kids | G48: 7 | H48: How Does Rain Form? | I48: How Does Rain Form? 🚀 | Science for Kids | Tiny Sparks | J48: 3–5 | K48: Short 9:16 | L48: 45–60 s | M48: Prof. Hoot + Leo (wrong guess) + Mila | N48: Answer simply: How Does Rain Form? | O48: Yes | P48: P1 | Q48: Idea | R48: =INDEX('Start Here'!$B$10:$B$16,WEEKDAY(C48,2)) | S48: =MOD(R48+'Start Here'!$B$6/24,1)
... A801: 800 | B801: =INT((A801-1)/7)+1 | C801: ='Start Here'!$B$5+A801-1 | D801: =TEXT(C801,"ddd") | E801: Story Season | F801: 📚 Moral Stories | G801: 100 | H801: The Greatest Treasure: Friendship | I801: The Greatest Treasure: Friendship 📚 | Moral Stories for Kids | Tiny Sparks | J801: 3–5 | K801: Long 16:9 + Short teaser | L801: 3–5 min (Short: 50 s) | M801: narrator + guest animals / Mila & Leo | N801: Value: friendship | O801: Yes | P801: P3 | Q801: Idea | R801: =INDEX('Start Here'!$B$10:$B$16,WEEKDAY(C801,2)) | S801: =MOD(R801+'Start Here'!$B$6/24,1)

Sheet Niche Progress
A1: Niche | B1: Skill | C1: Videos | D1: Scripted | E1: Rendered | F1: Scheduled | G1: Published | H1: % published | I1: First post | J1: Last post | K1: Need new species
A2: 🧠 Educational Stories | B2: kids-stories | C2: =COUNTIFS(Calendar!$F$2:$F$801,$A2) | D2: =COUNTIFS(Calendar!$F$2:$F$801,$A2,Calendar!$Q$2:$Q$801,"Scripted") | E2: =COUNTIFS(Calendar!$F$2:$F$801,$A2,Calendar!$Q$2:$Q$801,"Rendered") | F2: =COUNTIFS(Calendar!$F$2:$F$801,$A2,Calendar!$Q$2:$Q$801,"Scheduled") | G2: =COUNTIFS(Calendar!$F$2:$F$801,$A2,Calendar!$Q$2:$Q$801,"Published") | H2: =IF(C2=0,0,G2/C2) | I2: =_xlfn.MINIFS(Calendar!$C$2:$C$801,Calendar!$F$2:$F$801,$A2) | J2: =_xlfn.MAXIFS(Calendar!$C$2:$C$801,Calendar!$F$2:$F$801,$A2) | K2: =COUNTIFS(Calendar!$F$2:$F$801,$A2,Calendar!$O$2:$O$801,"Build first*")
A3: 🔢 Numbers & Math | B3: kids-numbers | C3: =COUNTIFS(Calendar!$F$2:$F$801,$A3) | D3: =COUNTIFS(Calendar!$F$2:$F$801,$A3,Calendar!$Q$2:$Q$801,"Scripted") | E3: =COUNTIFS(Calendar!$F$2:$F$801,$A3,Calendar!$Q$2:$Q$801,"Rendered") | F3: =COUNTIFS(Calendar!$F$2:$F$801,$A3,Calendar!$Q$2:$Q$801,"Scheduled") | G3: =COUNTIFS(Calendar!$F$2:$F$801,$A3,Calendar!$Q$2:$Q$801,"Published") | H3: =IF(C3=0,0,G3/C3) | I3: =_xlfn.MINIFS(Calendar!$C$2:$C$801,Calendar!$F$2:$F$801,$A3) | J3: =_xlfn.MAXIFS(Calendar!$C$2:$C$801,Calendar!$F$2:$F$801,$A3) | K3: =COUNTIFS(Calendar!$F$2:$F$801,$A3,Calendar!$O$2:$O$801,"Build first*")
A4: 🔤 English/French Words | B4: kids-words | C4: =COUNTIFS(Calendar!$F$2:$F$801,$A4) | D4: =COUNTIFS(Calendar!$F$2:$F$801,$A4,Calendar!$Q$2:$Q$801,"Scripted") | E4: =COUNTIFS(Calendar!$F$2:$F$801,$A4,Calendar!$Q$2:$Q$801,"Rendered") | F4: =COUNTIFS(Calendar!$F$2:$F$801,$A4,Calendar!$Q$2:$Q$801,"Scheduled") | G4: =COUNTIFS(Calendar!$F$2:$F$801,$A4,Calendar!$Q$2:$Q$801,"Published") | H4: =IF(C4=0,0,G4/C4) | I4: =_xlfn.MINIFS(Calendar!$C$2:$C$801,Calendar!$F$2:$F$801,$A4) | J4: =_xlfn.MAXIFS(Calendar!$C$2:$C$801,Calendar!$F$2:$F$801,$A4) | K4: =COUNTIFS(Calendar!$F$2:$F$801,$A4,Calendar!$O$2:$O$801,"Build first*")
A5: 🦁 Animal Stories | B5: kids-animals | C5: =COUNTIFS(Calendar!$F$2:$F$801,$A5) | D5: =COUNTIFS(Calendar!$F$2:$F$801,$A5,Calendar!$Q$2:$Q$801,"Scripted") | E5: =COUNTIFS(Calendar!$F$2:$F$801,$A5,Calendar!$Q$2:$Q$801,"Rendered") | F5: =COUNTIFS(Calendar!$F$2:$F$801,$A5,Calendar!$Q$2:$Q$801,"Scheduled") | G5: =COUNTIFS(Calendar!$F$2:$F$801,$A5,Calendar!$Q$2:$Q$801,"Published") | H5: =IF(C5=0,0,G5/C5) | I5: =_xlfn.MINIFS(Calendar!$C$2:$C$801,Calendar!$F$2:$F$801,$A5) | J5: =_xlfn.MAXIFS(Calendar!$C$2:$C$801,Calendar!$F$2:$F$801,$A5) | K5: =COUNTIFS(Calendar!$F$2:$F$801,$A5,Calendar!$O$2:$O$801,"Build first*")
A6: 🚀 Science for Kids | B6: kids-science | C6: =COUNTIFS(Calendar!$F$2:$F$801,$A6) | D6: =COUNTIFS(Calendar!$F$2:$F$801,$A6,Calendar!$Q$2:$Q$801,"Scripted") | E6: =COUNTIFS(Calendar!$F$2:$F$801,$A6,Calendar!$Q$2:$Q$801,"Rendered") | F6: =COUNTIFS(Calendar!$F$2:$F$801,$A6,Calendar!$Q$2:$Q$801,"Scheduled") | G6: =COUNTIFS(Calendar!$F$2:$F$801,$A6,Calendar!$Q$2:$Q$801,"Published") | H6: =IF(C6=0,0,G6/C6) | I6: =_xlfn.MINIFS(Calendar!$C$2:$C$801,Calendar!$F$2:$F$801,$A6) | J6: =_xlfn.MAXIFS(Calendar!$C$2:$C$801,Calendar!$F$2:$F$801,$A6) | K6: =COUNTIFS(Calendar!$F$2:$F$801,$A6,Calendar!$O$2:$O$801,"Build first*")
A7: 🧩 Puzzles & Problem-Solving | B7: kids-puzzles | C7: =COUNTIFS(Calendar!$F$2:$F$801,$A7) | D7: =COUNTIFS(Calendar!$F$2:$F$801,$A7,Calendar!$Q$2:$Q$801,"Scripted") | E7: =COUNTIFS(Calendar!$F$2:$F$801,$A7,Calendar!$Q$2:$Q$801,"Rendered") | F7: =COUNTIFS(Calendar!$F$2:$F$801,$A7,Calendar!$Q$2:$Q$801,"Scheduled") | G7: =COUNTIFS(Calendar!$F$2:$F$801,$A7,Calendar!$Q$2:$Q$801,"Published") | H7: =IF(C7=0,0,G7/C7) | I7: =_xlfn.MINIFS(Calendar!$C$2:$C$801,Calendar!$F$2:$F$801,$A7) | J7: =_xlfn.MAXIFS(Calendar!$C$2:$C$801,Calendar!$F$2:$F$801,$A7) | K7: =COUNTIFS(Calendar!$F$2:$F$801,$A7,Calendar!$O$2:$O$801,"Build first*")
A8: 📚 Moral Stories | B8: kids-morals | C8: =COUNTIFS(Calendar!$F$2:$F$801,$A8) | D8: =COUNTIFS(Calendar!$F$2:$F$801,$A8,Calendar!$Q$2:$Q$801,"Scripted") | E8: =COUNTIFS(Calendar!$F$2:$F$801,$A8,Calendar!$Q$2:$Q$801,"Rendered") | F8: =COUNTIFS(Calendar!$F$2:$F$801,$A8,Calendar!$Q$2:$Q$801,"Scheduled") | G8: =COUNTIFS(Calendar!$F$2:$F$801,$A8,Calendar!$Q$2:$Q$801,"Published") | H8: =IF(C8=0,0,G8/C8) | I8: =_xlfn.MINIFS(Calendar!$C$2:$C$801,Calendar!$F$2:$F$801,$A8) | J8: =_xlfn.MAXIFS(Calendar!$C$2:$C$801,Calendar!$F$2:$F$801,$A8) | K8: =COUNTIFS(Calendar!$F$2:$F$801,$A8,Calendar!$O$2:$O$801,"Build first*")
A9: 🎵 Educational Songs | B9: kids-songs | C9: =COUNTIFS(Calendar!$F$2:$F$801,$A9) | D9: =COUNTIFS(Calendar!$F$2:$F$801,$A9,Calendar!$Q$2:$Q$801,"Scripted") | E9: =COUNTIFS(Calendar!$F$2:$F$801,$A9,Calendar!$Q$2:$Q$801,"Rendered") | F9: =COUNTIFS(Calendar!$F$2:$F$801,$A9,Calendar!$Q$2:$Q$801,"Scheduled") | G9: =COUNTIFS(Calendar!$F$2:$F$801,$A9,Calendar!$Q$2:$Q$801,"Published") | H9: =IF(C9=0,0,G9/C9) | I9: =_xlfn.MINIFS(Calendar!$C$2:$C$801,Calendar!$F$2:$F$801,$A9) | J9: =_xlfn.MAXIFS(Calendar!$C$2:$C$801,Calendar!$F$2:$F$801,$A9) | K9: =COUNTIFS(Calendar!$F$2:$F$801,$A9,Calendar!$O$2:$O$801,"Build first*")
A10: Total | C10: =SUM(C2:C9) | D10: =SUM(D2:D9) | E10: =SUM(E2:E9) | F10: =SUM(F2:F9) | G10: =SUM(G2:G9) | H10: =IF(C10=0,0,G10/C10) | K10: =SUM(K2:K9)

Sheet Weekly Stats
A1: Week | B1: Week starts | C1: Planned | D1: Published | E1: Views (7 days) | F1: Subs gained | G1: Avg % viewed
A2: 1 | B2: ='Start Here'!$B$5+0 | C2: =COUNTIFS(Calendar!$B$2:$B$801,$A2) | D2: =COUNTIFS(Calendar!$B$2:$B$801,$A2,Calendar!$Q$2:$Q$801,"Published") | E2: =SUMIFS(Calendar!$V$2:$V$801,Calendar!$B$2:$B$801,$A2) | F2: =SUMIFS(Calendar!$W$2:$W$801,Calendar!$B$2:$B$801,$A2) | G2: =IFERROR(AVERAGEIFS(Calendar!$X$2:$X$801,Calendar!$B$2:$B$801,$A2,Calendar!$X$2:$X$801,">0"),0)
A3: 2 | B3: ='Start Here'!$B$5+7 | C3: =COUNTIFS(Calendar!$B$2:$B$801,$A3) | D3: =COUNTIFS(Calendar!$B$2:$B$801,$A3,Calendar!$Q$2:$Q$801,"Published") | E3: =SUMIFS(Calendar!$V$2:$V$801,Calendar!$B$2:$B$801,$A3) | F3: =SUMIFS(Calendar!$W$2:$W$801,Calendar!$B$2:$B$801,$A3) | G3: =IFERROR(AVERAGEIFS(Calendar!$X$2:$X$801,Calendar!$B$2:$B$801,$A3,Calendar!$X$2:$X$801,">0"),0)
A4: 3 | B4: ='Start Here'!$B$5+14 | C4: =COUNTIFS(Calendar!$B$2:$B$801,$A4) | D4: =COUNTIFS(Calendar!$B$2:$B$801,$A4,Calendar!$Q$2:$Q$801,"Published") | E4: =SUMIFS(Calendar!$V$2:$V$801,Calendar!$B$2:$B$801,$A4) | F4: =SUMIFS(Calendar!$W$2:$W$801,Calendar!$B$2:$B$801,$A4) | G4: =IFERROR(AVERAGEIFS(Calendar!$X$2:$X$801,Calendar!$B$2:$B$801,$A4,Calendar!$X$2:$X$801,">0"),0)
A5: 4 | B5: ='Start Here'!$B$5+21 | C5: =COUNTIFS(Calendar!$B$2:$B$801,$A5) | D5: =COUNTIFS(Calendar!$B$2:$B$801,$A5,Calendar!$Q$2:$Q$801,"Published") | E5: =SUMIFS(Calendar!$V$2:$V$801,Calendar!$B$2:$B$801,$A5) | F5: =SUMIFS(Calendar!$W$2:$W$801,Calendar!$B$2:$B$801,$A5) | G5: =IFERROR(AVERAGEIFS(Calendar!$X$2:$X$801,Calendar!$B$2:$B$801,$A5,Calendar!$X$2:$X$801,">0"),0)
A6: 5 | B6: ='Start Here'!$B$5+28 | C6: =COUNTIFS(Calendar!$B$2:$B$801,$A6) | D6: =COUNTIFS(Calendar!$B$2:$B$801,$A6,Calendar!$Q$2:$Q$801,"Published") | E6: =SUMIFS(Calendar!$V$2:$V$801,Calendar!$B$2:$B$801,$A6) | F6: =SUMIFS(Calendar!$W$2:$W$801,Calendar!$B$2:$B$801,$A6) | G6: =IFERROR(AVERAGEIFS(Calendar!$X$2:$X$801,Calendar!$B$2:$B$801,$A6,Calendar!$X$2:$X$801,">0"),0)
A7: 6 | B7: ='Start Here'!$B$5+35 | C7: =COUNTIFS(Calendar!$B$2:$B$801,$A7) | D7: =COUNTIFS(Calendar!$B$2:$B$801,$A7,Calendar!$Q$2:$Q$801,"Published") | E7: =SUMIFS(Calendar!$V$2:$V$801,Calendar!$B$2:$B$801,$A7) | F7: =SUMIFS(Calendar!$W$2:$W$801,Calendar!$B$2:$B$801,$A7) | G7: =IFERROR(AVERAGEIFS(Calendar!$X$2:$X$801,Calendar!$B$2:$B$801,$A7,Calendar!$X$2:$X$801,">0"),0)
A8: 7 | B8: ='Start Here'!$B$5+42 | C8: =COUNTIFS(Calendar!$B$2:$B$801,$A8) | D8: =COUNTIFS(Calendar!$B$2:$B$801,$A8,Calendar!$Q$2:$Q$801,"Published") | E8: =SUMIFS(Calendar!$V$2:$V$801,Calendar!$B$2:$B$801,$A8) | F8: =SUMIFS(Calendar!$W$2:$W$801,Calendar!$B$2:$B$801,$A8) | G8: =IFERROR(AVERAGEIFS(Calendar!$X$2:$X$801,Calendar!$B$2:$B$801,$A8,Calendar!$X$2:$X$801,">0"),0)
A9: 8 | B9: ='Start Here'!$B$5+49 | C9: =COUNTIFS(Calendar!$B$2:$B$801,$A9) | D9: =COUNTIFS(Calendar!$B$2:$B$801,$A9,Calendar!$Q$2:$Q$801,"Published") | E9: =SUMIFS(Calendar!$V$2:$V$801,Calendar!$B$2:$B$801,$A9) | F9: =SUMIFS(Calendar!$W$2:$W$801,Calendar!$B$2:$B$801,$A9) | G9: =IFERROR(AVERAGEIFS(Calendar!$X$2:$X$801,Calendar!$B$2:$B$801,$A9,Calendar!$X$2:$X$801,">0"),0)
A10: 9 | B10: ='Start Here'!$B$5+56 | C10: =COUNTIFS(Calendar!$B$2:$B$801,$A10) | D10: =COUNTIFS(Calendar!$B$2:$B$801,$A10,Calendar!$Q$2:$Q$801,"Published") | E10: =SUMIFS(Calendar!$V$2:$V$801,Calendar!$B$2:$B$801,$A10) | F10: =SUMIFS(Calendar!$W$2:$W$801,Calendar!$B$2:$B$801,$A10) | G10: =IFERROR(AVERAGEIFS(Calendar!$X$2:$X$801,Calendar!$B$2:$B$801,$A10,Calendar!$X$2:$X$801,">0"),0)
A11: 10 | B11: ='Start Here'!$B$5+63 | C11: =COUNTIFS(Calendar!$B$2:$B$801,$A11) | D11: =COUNTIFS(Calendar!$B$2:$B$801,$A11,Calendar!$Q$2:$Q$801,"Published") | E11: =SUMIFS(Calendar!$V$2:$V$801,Calendar!$B$2:$B$801,$A11) | F11: =SUMIFS(Calendar!$W$2:$W$801,Calendar!$B$2:$B$801,$A11) | G11: =IFERROR(AVERAGEIFS(Calendar!$X$2:$X$801,Calendar!$B$2:$B$801,$A11,Calendar!$X$2:$X$801,">0"),0)
A12: 11 | B12: ='Start Here'!$B$5+70 | C12: =COUNTIFS(Calendar!$B$2:$B$801,$A12) | D12: =COUNTIFS(Calendar!$B$2:$B$801,$A12,Calendar!$Q$2:$Q$801,"Published") | E12: =SUMIFS(Calendar!$V$2:$V$801,Calendar!$B$2:$B$801,$A12) | F12: =SUMIFS(Calendar!$W$2:$W$801,Calendar!$B$2:$B$801,$A12) | G12: =IFERROR(AVERAGEIFS(Calendar!$X$2:$X$801,Calendar!$B$2:$B$801,$A12,Calendar!$X$2:$X$801,">0"),0)
A13: 12 | B13: ='Start Here'!$B$5+77 | C13: =COUNTIFS(Calendar!$B$2:$B$801,$A13) | D13: =COUNTIFS(Calendar!$B$2:$B$801,$A13,Calendar!$Q$2:$Q$801,"Published") | E13: =SUMIFS(Calendar!$V$2:$V$801,Calendar!$B$2:$B$801,$A13) | F13: =SUMIFS(Calendar!$W$2:$W$801,Calendar!$B$2:$B$801,$A13) | G13: =IFERROR(AVERAGEIFS(Calendar!$X$2:$X$801,Calendar!$B$2:$B$801,$A13,Calendar!$X$2:$X$801,">0"),0)
A14: 13 | B14: ='Start Here'!$B$5+84 | C14: =COUNTIFS(Calendar!$B$2:$B$801,$A14) | D14: =COUNTIFS(Calendar!$B$2:$B$801,$A14,Calendar!$Q$2:$Q$801,"Published") | E14: =SUMIFS(Calendar!$V$2:$V$801,Calendar!$B$2:$B$801,$A14) | F14: =SUMIFS(Calendar!$W$2:$W$801,Calendar!$B$2:$B$801,$A14) | G14: =IFERROR(AVERAGEIFS(Calendar!$X$2:$X$801,Calendar!$B$2:$B$801,$A14,Calendar!$X$2:$X$801,">0"),0)
A15: 14 | B15: ='Start Here'!$B$5+91 | C15: =COUNTIFS(Calendar!$B$2:$B$801,$A15) | D15: =COUNTIFS(Calendar!$B$2:$B$801,$A15,Calendar!$Q$2:$Q$801,"Published") | E15: =SUMIFS(Calendar!$V$2:$V$801,Calendar!$B$2:$B$801,$A15) | F15: =SUMIFS(Calendar!$W$2:$W$801,Calendar!$B$2:$B$801,$A15) | G15: =IFERROR(AVERAGEIFS(Calendar!$X$2:$X$801,Calendar!$B$2:$B$801,$A15,Calendar!$X$2:$X$801,">0"),0)
A16: 15 | B16: ='Start Here'!$B$5+98 | C16: =COUNTIFS(Calendar!$B$2:$B$801,$A16) | D16: =COUNTIFS(Calendar!$B$2:$B$801,$A16,Calendar!$Q$2:$Q$801,"Published") | E16: =SUMIFS(Calendar!$V$2:$V$801,Calendar!$B$2:$B$801,$A16) | F16: =SUMIFS(Calendar!$W$2:$W$801,Calendar!$B$2:$B$801,$A16) | G16: =IFERROR(AVERAGEIFS(Calendar!$X$2:$X$801,Calendar!$B$2:$B$801,$A16,Calendar!$X$2:$X$801,">0"),0)
A17: 16 | B17: ='Start Here'!$B$5+105 | C17: =COUNTIFS(Calendar!$B$2:$B$801,$A17) | D17: =COUNTIFS(Calendar!$B$2:$B$801,$A17,Calendar!$Q$2:$Q$801,"Published") | E17: =SUMIFS(Calendar!$V$2:$V$801,Calendar!$B$2:$B$801,$A17) | F17: =SUMIFS(Calendar!$W$2:$W$801,Calendar!$B$2:$B$801,$A17) | G17: =IFERROR(AVERAGEIFS(Calendar!$X$2:$X$801,Calendar!$B$2:$B$801,$A17,Calendar!$X$2:$X$801,">0"),0)
A18: 17 | B18: ='Start Here'!$B$5+112 | C18: =COUNTIFS(Calendar!$B$2:$B$801,$A18) | D18: =COUNTIFS(Calendar!$B$2:$B$801,$A18,Calendar!$Q$2:$Q$801,"Published") | E18: =SUMIFS(Calendar!$V$2:$V$801,Calendar!$B$2:$B$801,$A18) | F18: =SUMIFS(Calendar!$W$2:$W$801,Calendar!$B$2:$B$801,$A18) | G18: =IFERROR(AVERAGEIFS(Calendar!$X$2:$X$801,Calendar!$B$2:$B$801,$A18,Calendar!$X$2:$X$801,">0"),0)
A19: 18 | B19: ='Start Here'!$B$5+119 | C19: =COUNTIFS(Calendar!$B$2:$B$801,$A19) | D19: =COUNTIFS(Calendar!$B$2:$B$801,$A19,Calendar!$Q$2:$Q$801,"Published") | E19: =SUMIFS(Calendar!$V$2:$V$801,Calendar!$B$2:$B$801,$A19) | F19: =SUMIFS(Calendar!$W$2:$W$801,Calendar!$B$2:$B$801,$A19) | G19: =IFERROR(AVERAGEIFS(Calendar!$X$2:$X$801,Calendar!$B$2:$B$801,$A19,Calendar!$X$2:$X$801,">0"),0)
A20: 19 | B20: ='Start Here'!$B$5+126 | C20: =COUNTIFS(Calendar!$B$2:$B$801,$A20) | D20: =COUNTIFS(Calendar!$B$2:$B$801,$A20,Calendar!$Q$2:$Q$801,"Published") | E20: =SUMIFS(Calendar!$V$2:$V$801,Calendar!$B$2:$B$801,$A20) | F20: =SUMIFS(Calendar!$W$2:$W$801,Calendar!$B$2:$B$801,$A20) | G20: =IFERROR(AVERAGEIFS(Calendar!$X$2:$X$801,Calendar!$B$2:$B$801,$A20,Calendar!$X$2:$X$801,">0"),0)
A21: 20 | B21: ='Start Here'!$B$5+133 | C21: =COUNTIFS(Calendar!$B$2:$B$801,$A21) | D21: =COUNTIFS(Calendar!$B$2:$B$801,$A21,Calendar!$Q$2:$Q$801,"Published") | E21: =SUMIFS(Calendar!$V$2:$V$801,Calendar!$B$2:$B$801,$A21) | F21: =SUMIFS(Calendar!$W$2:$W$801,Calendar!$B$2:$B$801,$A21) | G21: =IFERROR(AVERAGEIFS(Calendar!$X$2:$X$801,Calendar!$B$2:$B$801,$A21,Calendar!$X$2:$X$801,">0"),0)
A22: 21 | B22: ='Start Here'!$B$5+140 | C22: =COUNTIFS(Calendar!$B$2:$B$801,$A22) | D22: =COUNTIFS(Calendar!$B$2:$B$801,$A22,Calendar!$Q$2:$Q$801,"Published") | E22: =SUMIFS(Calendar!$V$2:$V$801,Calendar!$B$2:$B$801,$A22) | F22: =SUMIFS(Calendar!$W$2:$W$801,Calendar!$B$2:$B$801,$A22) | G22: =IFERROR(AVERAGEIFS(Calendar!$X$2:$X$801,Calendar!$B$2:$B$801,$A22,Calendar!$X$2:$X$801,">0"),0)
A23: 22 | B23: ='Start Here'!$B$5+147 | C23: =COUNTIFS(Calendar!$B$2:$B$801,$A23) | D23: =COUNTIFS(Calendar!$B$2:$B$801,$A23,Calendar!$Q$2:$Q$801,"Published") | E23: =SUMIFS(Calendar!$V$2:$V$801,Calendar!$B$2:$B$801,$A23) | F23: =SUMIFS(Calendar!$W$2:$W$801,Calendar!$B$2:$B$801,$A23) | G23: =IFERROR(AVERAGEIFS(Calendar!$X$2:$X$801,Calendar!$B$2:$B$801,$A23,Calendar!$X$2:$X$801,">0"),0)
A24: 23 | B24: ='Start Here'!$B$5+154 | C24: =COUNTIFS(Calendar!$B$2:$B$801,$A24) | D24: =COUNTIFS(Calendar!$B$2:$B$801,$A24,Calendar!$Q$2:$Q$801,"Published") | E24: =SUMIFS(Calendar!$V$2:$V$801,Calendar!$B$2:$B$801,$A24) | F24: =SUMIFS(Calendar!$W$2:$W$801,Calendar!$B$2:$B$801,$A24) | G24: =IFERROR(AVERAGEIFS(Calendar!$X$2:$X$801,Calendar!$B$2:$B$801,$A24,Calendar!$X$2:$X$801,">0"),0)
A25: 24 | B25: ='Start Here'!$B$5+161 | C25: =COUNTIFS(Calendar!$B$2:$B$801,$A25) | D25: =COUNTIFS(Calendar!$B$2:$B$801,$A25,Calendar!$Q$2:$Q$801,"Published") | E25: =SUMIFS(Calendar!$V$2:$V$801,Calendar!$B$2:$B$801,$A25) | F25: =SUMIFS(Calendar!$W$2:$W$801,Calendar!$B$2:$B$801,$A25) | G25: =IFERROR(AVERAGEIFS(Calendar!$X$2:$X$801,Calendar!$B$2:$B$801,$A25,Calendar!$X$2:$X$801,">0"),0)
A26: 25 | B26: ='Start Here'!$B$5+168 | C26: =COUNTIFS(Calendar!$B$2:$B$801,$A26) | D26: =COUNTIFS(Calendar!$B$2:$B$801,$A26,Calendar!$Q$2:$Q$801,"Published") | E26: =SUMIFS(Calendar!$V$2:$V$801,Calendar!$B$2:$B$801,$A26) | F26: =SUMIFS(Calendar!$W$2:$W$801,Calendar!$B$2:$B$801,$A26) | G26: =IFERROR(AVERAGEIFS(Calendar!$X$2:$X$801,Calendar!$B$2:$B$801,$A26,Calendar!$X$2:$X$801,">0"),0)
A27: 26 | B27: ='Start Here'!$B$5+175 | C27: =COUNTIFS(Calendar!$B$2:$B$801,$A27) | D27: =COUNTIFS(Calendar!$B$2:$B$801,$A27,Calendar!$Q$2:$Q$801,"Published") | E27: =SUMIFS(Calendar!$V$2:$V$801,Calendar!$B$2:$B$801,$A27) | F27: =SUMIFS(Calendar!$W$2:$W$801,Calendar!$B$2:$B$801,$A27) | G27: =IFERROR(AVERAGEIFS(Calendar!$X$2:$X$801,Calendar!$B$2:$B$801,$A27,Calendar!$X$2:$X$801,">0"),0)
A28: 27 | B28: ='Start Here'!$B$5+182 | C28: =COUNTIFS(Calendar!$B$2:$B$801,$A28) | D28: =COUNTIFS(Calendar!$B$2:$B$801,$A28,Calendar!$Q$2:$Q$801,"Published") | E28: =SUMIFS(Calendar!$V$2:$V$801,Calendar!$B$2:$B$801,$A28) | F28: =SUMIFS(Calendar!$W$2:$W$801,Calendar!$B$2:$B$801,$A28) | G28: =IFERROR(AVERAGEIFS(Calendar!$X$2:$X$801,Calendar!$B$2:$B$801,$A28,Calendar!$X$2:$X$801,">0"),0)
A29: 28 | B29: ='Start Here'!$B$5+189 | C29: =COUNTIFS(Calendar!$B$2:$B$801,$A29) | D29: =COUNTIFS(Calendar!$B$2:$B$801,$A29,Calendar!$Q$2:$Q$801,"Published") | E29: =SUMIFS(Calendar!$V$2:$V$801,Calendar!$B$2:$B$801,$A29) | F29: =SUMIFS(Calendar!$W$2:$W$801,Calendar!$B$2:$B$801,$A29) | G29: =IFERROR(AVERAGEIFS(Calendar!$X$2:$X$801,Calendar!$B$2:$B$801,$A29,Calendar!$X$2:$X$801,">0"),0)
A30: 29 | B30: ='Start Here'!$B$5+196 | C30: =COUNTIFS(Calendar!$B$2:$B$801,$A30) | D30: =COUNTIFS(Calendar!$B$2:$B$801,$A30,Calendar!$Q$2:$Q$801,"Published") | E30: =SUMIFS(Calendar!$V$2:$V$801,Calendar!$B$2:$B$801,$A30) | F30: =SUMIFS(Calendar!$W$2:$W$801,Calendar!$B$2:$B$801,$A30) | G30: =IFERROR(AVERAGEIFS(Calendar!$X$2:$X$801,Calendar!$B$2:$B$801,$A30,Calendar!$X$2:$X$801,">0"),0)
A31: 30 | B31: ='Start Here'!$B$5+203 | C31: =COUNTIFS(Calendar!$B$2:$B$801,$A31) | D31: =COUNTIFS(Calendar!$B$2:$B$801,$A31,Calendar!$Q$2:$Q$801,"Published") | E31: =SUMIFS(Calendar!$V$2:$V$801,Calendar!$B$2:$B$801,$A31) | F31: =SUMIFS(Calendar!$W$2:$W$801,Calendar!$B$2:$B$801,$A31) | G31: =IFERROR(AVERAGEIFS(Calendar!$X$2:$X$801,Calendar!$B$2:$B$801,$A31,Calendar!$X$2:$X$801,">0"),0)
A32: 31 | B32: ='Start Here'!$B$5+210 | C32: =COUNTIFS(Calendar!$B$2:$B$801,$A32) | D32: =COUNTIFS(Calendar!$B$2:$B$801,$A32,Calendar!$Q$2:$Q$801,"Published") | E32: =SUMIFS(Calendar!$V$2:$V$801,Calendar!$B$2:$B$801,$A32) | F32: =SUMIFS(Calendar!$W$2:$W$801,Calendar!$B$2:$B$801,$A32) | G32: =IFERROR(AVERAGEIFS(Calendar!$X$2:$X$801,Calendar!$B$2:$B$801,$A32,Calendar!$X$2:$X$801,">0"),0)
A33: 32 | B33: ='Start Here'!$B$5+217 | C33: =COUNTIFS(Calendar!$B$2:$B$801,$A33) | D33: =COUNTIFS(Calendar!$B$2:$B$801,$A33,Calendar!$Q$2:$Q$801,"Published") | E33: =SUMIFS(Calendar!$V$2:$V$801,Calendar!$B$2:$B$801,$A33) | F33: =SUMIFS(Calendar!$W$2:$W$801,Calendar!$B$2:$B$801,$A33) | G33: =IFERROR(AVERAGEIFS(Calendar!$X$2:$X$801,Calendar!$B$2:$B$801,$A33,Calendar!$X$2:$X$801,">0"),0)
A34: 33 | B34: ='Start Here'!$B$5+224 | C34: =COUNTIFS(Calendar!$B$2:$B$801,$A34) | D34: =COUNTIFS(Calendar!$B$2:$B$801,$A34,Calendar!$Q$2:$Q$801,"Published") | E34: =SUMIFS(Calendar!$V$2:$V$801,Calendar!$B$2:$B$801,$A34) | F34: =SUMIFS(Calendar!$W$2:$W$801,Calendar!$B$2:$B$801,$A34) | G34: =IFERROR(AVERAGEIFS(Calendar!$X$2:$X$801,Calendar!$B$2:$B$801,$A34,Calendar!$X$2:$X$801,">0"),0)
A35: 34 | B35: ='Start Here'!$B$5+231 | C35: =COUNTIFS(Calendar!$B$2:$B$801,$A35) | D35: =COUNTIFS(Calendar!$B$2:$B$801,$A35,Calendar!$Q$2:$Q$801,"Published") | E35: =SUMIFS(Calendar!$V$2:$V$801,Calendar!$B$2:$B$801,$A35) | F35: =SUMIFS(Calendar!$W$2:$W$801,Calendar!$B$2:$B$801,$A35) | G35: =IFERROR(AVERAGEIFS(Calendar!$X$2:$X$801,Calendar!$B$2:$B$801,$A35,Calendar!$X$2:$X$801,">0"),0)
A36: 35 | B36: ='Start Here'!$B$5+238 | C36: =COUNTIFS(Calendar!$B$2:$B$801,$A36) | D36: =COUNTIFS(Calendar!$B$2:$B$801,$A36,Calendar!$Q$2:$Q$801,"Published") | E36: =SUMIFS(Calendar!$V$2:$V$801,Calendar!$B$2:$B$801,$A36) | F36: =SUMIFS(Calendar!$W$2:$W$801,Calendar!$B$2:$B$801,$A36) | G36: =IFERROR(AVERAGEIFS(Calendar!$X$2:$X$801,Calendar!$B$2:$B$801,$A36,Calendar!$X$2:$X$801,">0"),0)
A37: 36 | B37: ='Start Here'!$B$5+245 | C37: =COUNTIFS(Calendar!$B$2:$B$801,$A37) | D37: =COUNTIFS(Calendar!$B$2:$B$801,$A37,Calendar!$Q$2:$Q$801,"Published") | E37: =SUMIFS(Calendar!$V$2:$V$801,Calendar!$B$2:$B$801,$A37) | F37: =SUMIFS(Calendar!$W$2:$W$801,Calendar!$B$2:$B$801,$A37) | G37: =IFERROR(AVERAGEIFS(Calendar!$X$2:$X$801,Calendar!$B$2:$B$801,$A37,Calendar!$X$2:$X$801,">0"),0)
A38: 37 | B38: ='Start Here'!$B$5+252 | C38: =COUNTIFS(Calendar!$B$2:$B$801,$A38) | D38: =COUNTIFS(Calendar!$B$2:$B$801,$A38,Calendar!$Q$2:$Q$801,"Published") | E38: =SUMIFS(Calendar!$V$2:$V$801,Calendar!$B$2:$B$801,$A38) | F38: =SUMIFS(Calendar!$W$2:$W$801,Calendar!$B$2:$B$801,$A38) | G38: =IFERROR(AVERAGEIFS(Calendar!$X$2:$X$801,Calendar!$B$2:$B$801,$A38,Calendar!$X$2:$X$801,">0"),0)
A39: 38 | B39: ='Start Here'!$B$5+259 | C39: =COUNTIFS(Calendar!$B$2:$B$801,$A39) | D39: =COUNTIFS(Calendar!$B$2:$B$801,$A39,Calendar!$Q$2:$Q$801,"Published") | E39: =SUMIFS(Calendar!$V$2:$V$801,Calendar!$B$2:$B$801,$A39) | F39: =SUMIFS(Calendar!$W$2:$W$801,Calendar!$B$2:$B$801,$A39) | G39: =IFERROR(AVERAGEIFS(Calendar!$X$2:$X$801,Calendar!$B$2:$B$801,$A39,Calendar!$X$2:$X$801,">0"),0)
A40: 39 | B40: ='Start Here'!$B$5+266 | C40: =COUNTIFS(Calendar!$B$2:$B$801,$A40) | D40: =COUNTIFS(Calendar!$B$2:$B$801,$A40,Calendar!$Q$2:$Q$801,"Published") | E40: =SUMIFS(Calendar!$V$2:$V$801,Calendar!$B$2:$B$801,$A40) | F40: =SUMIFS(Calendar!$W$2:$W$801,Calendar!$B$2:$B$801,$A40) | G40: =IFERROR(AVERAGEIFS(Calendar!$X$2:$X$801,Calendar!$B$2:$B$801,$A40,Calendar!$X$2:$X$801,">0"),0)
...

Sheet Posting Guide
A1: Posting Guide — Tiny Sparks
A3: Cadence | B3: One video a day on fixed theme days (see Start Here). Consistency beats volume: never skip a theme day. If daily is too much, publish Mon/Wed/Fri/Sun and keep the same order — just change Day # spacing.
A4: Batching | B4: Produce a full week (7 videos, one per niche) in one session and schedule them all in YouTube Studio (Status = Scheduled). Keep a buffer of 2 weeks ahead.
A5: Shorts + long | B5: Stories, morals, animal stories and songs are long 16:9 episodes + a 45–60 s Short cut posted the same day at 18:00 ET. Math, words, science and puzzles are mostly Shorts; their "Ultimate / Quiz / 20…" ideas are long.
A6: Compilations | B6: Every 4 weeks, stitch the month's long episodes of one niche into a 20–30 min compilation and post it on a Saturday at 9:00 ET (extra slot) — the watch-time engine of kids channels.
A7: Every upload | B7: Made for Kids = YES · title from the Calendar · description = what kids learn (2 lines) + ages + lyrics for songs · playlist per niche · thumbnail (long videos): one big face + 1–3 words · Altered/synthetic content = No.
A8: After upload | B8: Paste the link · after 48 h and 7 days type the views · Avg % viewed (Shorts > 70 %, long > 40 % is good) · note what worked.
A9: Times | B9: Weekdays 16:00 ET (after school / nap), weekends 09:00 ET (morning). These are starting points; after ~4 weeks use YouTube Analytics → Audience → "When your viewers are on YouTube" and update the time table on Start Here.
A10: Quality bar | B10: Original characters, original scripts, original songs (tools/gen_song.py), real teaching value and genuine variation in every video. YouTube demonetises mass-produced, near-identical kids videos (inauthentic content) — the niche skills enforce the variety.
A11: Language | B11: English is the primary language (US audience); French is the bonus line ("Learn 20 Animals in English & French"). A full French channel can come later by re-voicing the same videos.
A12: Art to-do | B12: Filter the Calendar column "Rig ready?" ≠ Yes within Priority P1: that is the list of animal species to add to the Critter rig before those days.
